<?xml version="1.0" encoding="UTF-8"?>
<testng-results skipped="0" failed="4" total="4" passed="0">
  <reporter-output>
  </reporter-output>
  <suite name="Suite" duration-ms="31" started-at="2013-07-31T23:28:06Z" finished-at="2013-07-31T23:28:06Z">
    <groups>
    </groups>
    <test name="Test" duration-ms="31" started-at="2013-07-31T23:28:06Z" finished-at="2013-07-31T23:28:06Z">
      <class name="com.ts.main.Comandos">
        <test-method status="PASS" signature="setUp()[pri:0, instance:com.ts.main.Comandos@2d2c6ed8]" name="setUp" is-config="true" duration-ms="15" started-at="2013-07-31T17:28:06Z" finished-at="2013-07-31T17:28:06Z">
          <reporter-output>
          </reporter-output>
        </test-method> <!-- setUp -->
        <test-method status="FAIL" signature="agregarEdificioTest()[pri:0, instance:com.ts.main.Comandos@2d2c6ed8]" name="agregarEdificioTest" duration-ms="0" started-at="2013-07-31T17:28:06Z" finished-at="2013-07-31T17:28:06Z">
          <exception class="java.lang.ArrayIndexOutOfBoundsException">
            <message>
              <![CDATA[1]]>
            </message>
            <full-stacktrace>
              <![CDATA[java.lang.ArrayIndexOutOfBoundsException: 1
	at com.ts.main.InterpreteMandatos.interpreteCadena(InterpreteMandatos.java:56)
	at com.ts.main.InterpreteMandatos.ejecutaComando(InterpreteMandatos.java:82)
	at com.ts.main.Comandos.agregarEdificioTest(Comandos.java:49)
	at sun.reflect.NativeMethodAccessorImpl.invoke0(Native Method)
	at sun.reflect.NativeMethodAccessorImpl.invoke(NativeMethodAccessorImpl.java:57)
	at sun.reflect.DelegatingMethodAccessorImpl.invoke(DelegatingMethodAccessorImpl.java:43)
	at java.lang.reflect.Method.invoke(Method.java:606)
	at org.testng.internal.MethodInvocationHelper.invokeMethod(MethodInvocationHelper.java:84)
	at org.testng.internal.Invoker.invokeMethod(Invoker.java:714)
	at org.testng.internal.Invoker.invokeTestMethod(Invoker.java:901)
	at org.testng.internal.Invoker.invokeTestMethods(Invoker.java:1231)
	at org.testng.internal.TestMethodWorker.invokeTestMethods(TestMethodWorker.java:127)
	at org.testng.internal.TestMethodWorker.run(TestMethodWorker.java:111)
	at org.testng.TestRunner.privateRun(TestRunner.java:767)
	at org.testng.TestRunner.run(TestRunner.java:617)
	at org.testng.SuiteRunner.runTest(SuiteRunner.java:335)
	at org.testng.SuiteRunner.runSequentially(SuiteRunner.java:330)
	at org.testng.SuiteRunner.privateRun(SuiteRunner.java:291)
	at org.testng.SuiteRunner.run(SuiteRunner.java:240)
	at org.testng.SuiteRunnerWorker.runSuite(SuiteRunnerWorker.java:52)
	at org.testng.SuiteRunnerWorker.run(SuiteRunnerWorker.java:86)
	at org.testng.TestNG.runSuitesSequentially(TestNG.java:1224)
	at org.testng.TestNG.runSuitesLocally(TestNG.java:1149)
	at org.testng.TestNG.run(TestNG.java:1057)
	at org.testng.remote.RemoteTestNG.run(RemoteTestNG.java:111)
	at org.testng.remote.RemoteTestNG.initAndRun(RemoteTestNG.java:204)
	at org.testng.remote.RemoteTestNG.main(RemoteTestNG.java:175)
]]>
            </full-stacktrace>
          </exception> <!-- java.lang.ArrayIndexOutOfBoundsException -->
          <reporter-output>
          </reporter-output>
        </test-method> <!-- agregarEdificioTest -->
        <test-method status="FAIL" signature="agregarCompanniaTest()[pri:0, instance:com.ts.main.Comandos@2d2c6ed8]" name="agregarCompanniaTest" duration-ms="0" started-at="2013-07-31T17:28:06Z" finished-at="2013-07-31T17:28:06Z">
          <exception class="java.lang.ArrayIndexOutOfBoundsException">
            <message>
              <![CDATA[1]]>
            </message>
            <full-stacktrace>
              <![CDATA[java.lang.ArrayIndexOutOfBoundsException: 1
	at com.ts.main.InterpreteMandatos.interpreteCadena(InterpreteMandatos.java:56)
	at com.ts.main.InterpreteMandatos.ejecutaComando(InterpreteMandatos.java:82)
	at com.ts.main.Comandos.agregarCompanniaTest(Comandos.java:37)
	at sun.reflect.NativeMethodAccessorImpl.invoke0(Native Method)
	at sun.reflect.NativeMethodAccessorImpl.invoke(NativeMethodAccessorImpl.java:57)
	at sun.reflect.DelegatingMethodAccessorImpl.invoke(DelegatingMethodAccessorImpl.java:43)
	at java.lang.reflect.Method.invoke(Method.java:606)
	at org.testng.internal.MethodInvocationHelper.invokeMethod(MethodInvocationHelper.java:84)
	at org.testng.internal.Invoker.invokeMethod(Invoker.java:714)
	at org.testng.internal.Invoker.invokeTestMethod(Invoker.java:901)
	at org.testng.internal.Invoker.invokeTestMethods(Invoker.java:1231)
	at org.testng.internal.TestMethodWorker.invokeTestMethods(TestMethodWorker.java:127)
	at org.testng.internal.TestMethodWorker.run(TestMethodWorker.java:111)
	at org.testng.TestRunner.privateRun(TestRunner.java:767)
	at org.testng.TestRunner.run(TestRunner.java:617)
	at org.testng.SuiteRunner.runTest(SuiteRunner.java:335)
	at org.testng.SuiteRunner.runSequentially(SuiteRunner.java:330)
	at org.testng.SuiteRunner.privateRun(SuiteRunner.java:291)
	at org.testng.SuiteRunner.run(SuiteRunner.java:240)
	at org.testng.SuiteRunnerWorker.runSuite(SuiteRunnerWorker.java:52)
	at org.testng.SuiteRunnerWorker.run(SuiteRunnerWorker.java:86)
	at org.testng.TestNG.runSuitesSequentially(TestNG.java:1224)
	at org.testng.TestNG.runSuitesLocally(TestNG.java:1149)
	at org.testng.TestNG.run(TestNG.java:1057)
	at org.testng.remote.RemoteTestNG.run(RemoteTestNG.java:111)
	at org.testng.remote.RemoteTestNG.initAndRun(RemoteTestNG.java:204)
	at org.testng.remote.RemoteTestNG.main(RemoteTestNG.java:175)
]]>
            </full-stacktrace>
          </exception> <!-- java.lang.ArrayIndexOutOfBoundsException -->
          <reporter-output>
          </reporter-output>
        </test-method> <!-- agregarCompanniaTest -->
        <test-method status="FAIL" signature="end()[pri:0, instance:com.ts.main.Comandos@2d2c6ed8]" name="end" is-config="true" duration-ms="0" started-at="2013-07-31T17:28:06Z" finished-at="2013-07-31T17:28:06Z">
          <exception class="java.lang.ArrayIndexOutOfBoundsException">
            <message>
              <![CDATA[1]]>
            </message>
            <full-stacktrace>
              <![CDATA[java.lang.ArrayIndexOutOfBoundsException: 1
	at com.ts.main.InterpreteMandatos.interpreteCadena(InterpreteMandatos.java:56)
	at com.ts.main.InterpreteMandatos.ejecutaComando(InterpreteMandatos.java:82)
	at com.ts.main.Comandos.end(Comandos.java:57)
	at sun.reflect.NativeMethodAccessorImpl.invoke0(Native Method)
	at sun.reflect.NativeMethodAccessorImpl.invoke(NativeMethodAccessorImpl.java:57)
	at sun.reflect.DelegatingMethodAccessorImpl.invoke(DelegatingMethodAccessorImpl.java:43)
	at java.lang.reflect.Method.invoke(Method.java:606)
	at org.testng.internal.MethodInvocationHelper.invokeMethod(MethodInvocationHelper.java:84)
	at org.testng.internal.Invoker.invokeConfigurationMethod(Invoker.java:564)
	at org.testng.internal.Invoker.invokeConfigurations(Invoker.java:213)
	at org.testng.internal.Invoker.invokeConfigurations(Invoker.java:138)
	at org.testng.TestRunner.afterRun(TestRunner.java:1014)
	at org.testng.TestRunner.run(TestRunner.java:621)
	at org.testng.SuiteRunner.runTest(SuiteRunner.java:335)
	at org.testng.SuiteRunner.runSequentially(SuiteRunner.java:330)
	at org.testng.SuiteRunner.privateRun(SuiteRunner.java:291)
	at org.testng.SuiteRunner.run(SuiteRunner.java:240)
	at org.testng.SuiteRunnerWorker.runSuite(SuiteRunnerWorker.java:52)
	at org.testng.SuiteRunnerWorker.run(SuiteRunnerWorker.java:86)
	at org.testng.TestNG.runSuitesSequentially(TestNG.java:1224)
	at org.testng.TestNG.runSuitesLocally(TestNG.java:1149)
	at org.testng.TestNG.run(TestNG.java:1057)
	at org.testng.remote.RemoteTestNG.run(RemoteTestNG.java:111)
	at org.testng.remote.RemoteTestNG.initAndRun(RemoteTestNG.java:204)
	at org.testng.remote.RemoteTestNG.main(RemoteTestNG.java:175)
]]>
            </full-stacktrace>
          </exception> <!-- java.lang.ArrayIndexOutOfBoundsException -->
          <reporter-output>
          </reporter-output>
        </test-method> <!-- end -->
      </class> <!-- com.ts.main.Comandos -->
      <class name="com.ts.main.InterpreteComandos">
        <test-method status="FAIL" signature="pruebaCargaArchivo()[pri:0, instance:com.ts.main.InterpreteComandos@7c1dea5]" name="pruebaCargaArchivo" duration-ms="0" started-at="2013-07-31T17:28:06Z" finished-at="2013-07-31T17:28:06Z">
          <exception class="java.lang.ArrayIndexOutOfBoundsException">
            <message>
              <![CDATA[1]]>
            </message>
            <full-stacktrace>
              <![CDATA[java.lang.ArrayIndexOutOfBoundsException: 1
	at com.ts.main.InterpreteMandatos.interpreteCadena(InterpreteMandatos.java:56)
	at com.ts.main.InterpreteMandatos.ejecutaComando(InterpreteMandatos.java:82)
	at com.ts.main.InterpreteMandatos.<init>(InterpreteMandatos.java:30)
	at com.ts.main.InterpreteComandos.pruebaCargaArchivo(InterpreteComandos.java:20)
	at sun.reflect.NativeMethodAccessorImpl.invoke0(Native Method)
	at sun.reflect.NativeMethodAccessorImpl.invoke(NativeMethodAccessorImpl.java:57)
	at sun.reflect.DelegatingMethodAccessorImpl.invoke(DelegatingMethodAccessorImpl.java:43)
	at java.lang.reflect.Method.invoke(Method.java:606)
	at org.testng.internal.MethodInvocationHelper.invokeMethod(MethodInvocationHelper.java:84)
	at org.testng.internal.Invoker.invokeMethod(Invoker.java:714)
	at org.testng.internal.Invoker.invokeTestMethod(Invoker.java:901)
	at org.testng.internal.Invoker.invokeTestMethods(Invoker.java:1231)
	at org.testng.internal.TestMethodWorker.invokeTestMethods(TestMethodWorker.java:127)
	at org.testng.internal.TestMethodWorker.run(TestMethodWorker.java:111)
	at org.testng.TestRunner.privateRun(TestRunner.java:767)
	at org.testng.TestRunner.run(TestRunner.java:617)
	at org.testng.SuiteRunner.runTest(SuiteRunner.java:335)
	at org.testng.SuiteRunner.runSequentially(SuiteRunner.java:330)
	at org.testng.SuiteRunner.privateRun(SuiteRunner.java:291)
	at org.testng.SuiteRunner.run(SuiteRunner.java:240)
	at org.testng.SuiteRunnerWorker.runSuite(SuiteRunnerWorker.java:52)
	at org.testng.SuiteRunnerWorker.run(SuiteRunnerWorker.java:86)
	at org.testng.TestNG.runSuitesSequentially(TestNG.java:1224)
	at org.testng.TestNG.runSuitesLocally(TestNG.java:1149)
	at org.testng.TestNG.run(TestNG.java:1057)
	at org.testng.remote.RemoteTestNG.run(RemoteTestNG.java:111)
	at org.testng.remote.RemoteTestNG.initAndRun(RemoteTestNG.java:204)
	at org.testng.remote.RemoteTestNG.main(RemoteTestNG.java:175)
]]>
            </full-stacktrace>
          </exception> <!-- java.lang.ArrayIndexOutOfBoundsException -->
          <reporter-output>
          </reporter-output>
        </test-method> <!-- pruebaCargaArchivo -->
        <test-method status="FAIL" signature="pruebaParseComandos()[pri:0, instance:com.ts.main.InterpreteComandos@7c1dea5]" name="pruebaParseComandos" duration-ms="0" started-at="2013-07-31T17:28:06Z" finished-at="2013-07-31T17:28:06Z">
          <exception class="java.lang.ArrayIndexOutOfBoundsException">
            <message>
              <![CDATA[1]]>
            </message>
            <full-stacktrace>
              <![CDATA[java.lang.ArrayIndexOutOfBoundsException: 1
	at com.ts.main.InterpreteMandatos.interpreteCadena(InterpreteMandatos.java:56)
	at com.ts.main.InterpreteMandatos.ejecutaComando(InterpreteMandatos.java:82)
	at com.ts.main.InterpreteMandatos.<init>(InterpreteMandatos.java:30)
	at com.ts.main.InterpreteComandos.pruebaParseComandos(InterpreteComandos.java:42)
	at sun.reflect.NativeMethodAccessorImpl.invoke0(Native Method)
	at sun.reflect.NativeMethodAccessorImpl.invoke(NativeMethodAccessorImpl.java:57)
	at sun.reflect.DelegatingMethodAccessorImpl.invoke(DelegatingMethodAccessorImpl.java:43)
	at java.lang.reflect.Method.invoke(Method.java:606)
	at org.testng.internal.MethodInvocationHelper.invokeMethod(MethodInvocationHelper.java:84)
	at org.testng.internal.Invoker.invokeMethod(Invoker.java:714)
	at org.testng.internal.Invoker.invokeTestMethod(Invoker.java:901)
	at org.testng.internal.Invoker.invokeTestMethods(Invoker.java:1231)
	at org.testng.internal.TestMethodWorker.invokeTestMethods(TestMethodWorker.java:127)
	at org.testng.internal.TestMethodWorker.run(TestMethodWorker.java:111)
	at org.testng.TestRunner.privateRun(TestRunner.java:767)
	at org.testng.TestRunner.run(TestRunner.java:617)
	at org.testng.SuiteRunner.runTest(SuiteRunner.java:335)
	at org.testng.SuiteRunner.runSequentially(SuiteRunner.java:330)
	at org.testng.SuiteRunner.privateRun(SuiteRunner.java:291)
	at org.testng.SuiteRunner.run(SuiteRunner.java:240)
	at org.testng.SuiteRunnerWorker.runSuite(SuiteRunnerWorker.java:52)
	at org.testng.SuiteRunnerWorker.run(SuiteRunnerWorker.java:86)
	at org.testng.TestNG.runSuitesSequentially(TestNG.java:1224)
	at org.testng.TestNG.runSuitesLocally(TestNG.java:1149)
	at org.testng.TestNG.run(TestNG.java:1057)
	at org.testng.remote.RemoteTestNG.run(RemoteTestNG.java:111)
	at org.testng.remote.RemoteTestNG.initAndRun(RemoteTestNG.java:204)
	at org.testng.remote.RemoteTestNG.main(RemoteTestNG.java:175)
]]>
            </full-stacktrace>
          </exception> <!-- java.lang.ArrayIndexOutOfBoundsException -->
          <reporter-output>
          </reporter-output>
        </test-method> <!-- pruebaParseComandos -->
      </class> <!-- com.ts.main.InterpreteComandos -->
    </test> <!-- Test -->
  </suite> <!-- Suite -->
</testng-results>
